2020-12-31 18:30:31.878 [error] <0.3542.0> Supervisor {<0.3542.0>,amqp_channel_sup_sup} had child channel_sup started with amqp_channel_sup:start_link(network, <0.3541.0>, <<"client 127.0.0.1:51399 -> 127.0.0.1:5672">>) at undefined exit with reason shutdown in context shutdown_error
2020-12-31 18:30:31.878 [error] <0.3418.0> Supervisor {<0.3418.0>,amqp_channel_sup_sup} had child channel_sup started with amqp_channel_sup:start_link(network, <0.3417.0>, <<"client 127.0.0.1:33943 -> 127.0.0.1:5672">>) at undefined exit with reason noproc in context shutdown_error
2020-12-31 18:30:31.879 [error] <0.3944.0> Supervisor {<0.3944.0>,amqp_channel_sup_sup} had child channel_sup started with amqp_channel_sup:start_link(network, <0.3943.0>, <<"client 127.0.0.1:34047 -> 127.0.0.1:5672">>) at undefined exit with reason shutdown in context shutdown_error
2020-12-31 18:30:31.879 [error] <0.4204.0> Supervisor {<0.4204.0>,amqp_channel_sup_sup} had child channel_sup started with amqp_channel_sup:start_link(network, <0.4203.0>, <<"client 127.0.0.1:42809 -> 127.0.0.1:5672">>) at undefined exit with reason noproc in context shutdown_error
2020-12-31 19:03:55.563 [error] <0.328.0> CRASH REPORT Process <0.328.0> with 0 neighbours exited with reason: #{'__exception__' => true,'__struct__' => 'Elixir.RuntimeError',message => <<"could not lookup Ecto repo Marketplace.Repo because it was not started or it does not exist">>} in 'Elixir.Ecto.Repo.Registry':lookup/1 line 19 in application_master:init/4 line 138
2020-12-31 19:52:13.871 [error] <0.328.0>@Elixir.Marketplace.Application:start CRASH REPORT Process <0.328.0> with 0 neighbours exited with reason: bad return value <0.344.0> from 'Elixir.Marketplace.Application':start(normal, []) in application_master:init/4 line 138
2020-12-31 19:55:31.658 [error] <0.328.0>@Elixir.Marketplace.Application:start CRASH REPORT Process <0.328.0> with 0 neighbours exited with reason: bad return value <0.362.0> from 'Elixir.Marketplace.Application':start(normal, []) in application_master:init/4 line 138
2020-12-31 20:11:37.066 [error] <0.322.0>@Elixir.Marketplace:start_server CRASH REPORT Process <0.322.0> with 0 neighbours exited with reason: call to undefined function 'Elixir.Marketplace':start_server() in application_master:init/4 line 138
2020-12-31 20:11:59.988 [error] <0.322.0>@Elixir.Marketplace:start_server CRASH REPORT Process <0.322.0> with 0 neighbours exited with reason: call to undefined function 'Elixir.Marketplace':start_server() in application_master:init/4 line 138
2020-12-31 20:12:34.569 [error] <0.328.0> CRASH REPORT Process <0.328.0> with 0 neighbours exited with reason: #{'__exception__' => true,'__struct__' => 'Elixir.RuntimeError',message => <<"could not lookup Ecto repo Marketplace.Repo because it was not started or it does not exist">>} in 'Elixir.Ecto.Repo.Registry':lookup/1 line 19 in application_master:init/4 line 138
2021-01-05 23:55:23.106 [error] <0.369.0>@Elixir.Marketplace:init:15 Supervisor 'Elixir.Marketplace.Supervisor' had child 'Elixir.Marketplace' started with 'Elixir.Marketplace':start_link([]) at undefined exit with reason no match of right hand value {error,unknown_host} in 'Elixir.Marketplace':init/1 line 15 in context start_error
